<?xml version="1.0" encoding="utf-8"?>
<!-- This URDF was automatically created by SolidWorks to URDF Exporter! Originally created by Stephen Brawner (brawner@gmail.com) 
     Commit Version: 1.5.1-0-g916b5db  Build Version: 1.5.7152.31018
     For more information, please see http://wiki.ros.org/sw_urdf_exporter -->
<robot name="robot_arm_urdf">
  
  <link name="world"/>
  
  <joint name="base_joint" type="fixed">
    <parent link="world"/>
    <child link="base_link"/>
    <origin rpy="0 0 0" xyz="0.0 0.0 0.00"/>
  </joint>
  
  <link name="base_link">
    <inertial>
      <origin xyz="4.1633E-17 0 0.073876" rpy="0 0 0" />
      <mass value="17.147" />
      <inertia ixx="0.192" ixy="-4.9423E-10" ixz="1.2752E-17"
               iyy="0.192" iyz="2.6417E-18" izz="0.29544" />
    </inertial>
    <visual>
      <origin xyz="0 0 0" rpy="0 0 0" />
      <geometry>
        <mesh filename="package://robot_arm_urdf/meshes/base_link.STL" />
      </geometry>
      <material name="">
        <color rgba="0.79216 0.81961 0.93333 1" />
      </material>
    </visual>
    <collision>
      <origin xyz="0 0 0" rpy="0 0 0" />
      <geometry>
        <mesh filename="package://robot_arm_urdf/meshes/base_link.STL" />
      </geometry>
    </collision>
  </link>
  
  <link name="link_1">
    <inertial>
      <origin xyz="-2.5757E-14 0.11047 -7.8988E-11" rpy="0 0 0" />
      <mass value="3.0905" />
      <inertia ixx="0.026302" ixy="-2.5267E-15" ixz="-1.4177E-12"
               iyy="0.019632" iyz="-7.4535E-12" izz="0.025388" />
    </inertial>
    <visual>
      <origin xyz="0 0 0" rpy="0 0 0" />
      <geometry>
        <mesh filename="package://robot_arm_urdf/meshes/link_1.STL" />
      </geometry>
      <material name="">
        <color rgba="1 1 1 1" />
      </material>
    </visual>
    <collision>
      <origin xyz="0 0 0" rpy="0 0 0" />
      <geometry>
        <mesh filename="package://robot_arm_urdf/meshes/link_1.STL" />
      </geometry>
    </collision>
  </link>
  
  <joint name="joint_1" type="revolute">
    <origin xyz="0 0 0.2" rpy="1.5708 0 1.5708" />
    <parent link="base_link" />
    <child link="link_1" />
    <axis xyz="0 1 0" />
    <limit lower="-3.142" upper="3.142" effort="300" velocity="6" />
  </joint>
  
  <!-- Define link_2, joint_2, link_3, joint_3, link_4, joint_4, link_5, joint_5, link_6, joint_6, link_7, joint_7 as per your URDF -->
  
  <!-- Skipping detailed definition for brevity -->
  
  <!-- Define link_2, joint_2, link_3, joint_3, link_4, joint_4, link_5, joint_5, link_6, joint_6, link_7, joint_7 as per your URDF -->
  
  <!-- Transmissions -->
  <transmission name="link_1_trans">
    <type>transmission_interface/SimpleTransmission</type>
    <joint name="joint_1">
      <hardwareInterface>hardware_interface/PositionJointInterface</hardwareInterface>
    </joint>
    <actuator name="link_1_motor">
      <hardwareInterface>hardware_interface/PositionJointInterface</hardwareInterface>
      <mechanicalReduction>1</mechanicalReduction>
    </actuator>
  </transmission>
  
  <!-- Repeat similar blocks for link_2_trans, link_3_trans, link_4_trans, link_5_trans, link_6_trans, link_7_trans -->
  
  <!-- Gazebo configuration -->
  <gazebo>
    <plugin name="control" filename="libgazebo_ros_control.so">
      <robotNamespace>/</robotNamespace>
    </plugin>
  </gazebo>
  
  <!-- Self-collision settings for each link -->
  <gazebo reference="link_1">
    <selfCollide>true</selfCollide>
  </gazebo>
  
  <!-- Repeat for link_2, link_3, link_4, link_5, link_6, link_7 -->

  <!-- Gazebo grasp plugin configuration -->
  <gazebo>
    <plugin name="gazebo_grasp_fix" filename="libgazebo_grasp_fix.so">
      <arm>
        <arm_name>robot_arm_urdf</arm_name>
        <palm_link>link_5</palm_link>
        <gripper_link>link_6</gripper_link>
        <gripper_link>link_7</gripper_link>
      </arm>
      <forces_angle_tolerance>100</forces_angle_tolerance>
      <update_rate>4</update_rate>
      <grip_count_threshold>4</grip_count_threshold>
      <max_grip_count>8</max_grip_count>
      <release_tolerance>0.0005</release_tolerance>
      <disable_collisions_on_attach>false</disable_collisions_on_attach>
      <contact_topic>__default_topic__</contact_topic>
    </plugin>
  </gazebo>

</robot>

